<?xml version="1.0" ?>
<robot name="upper_right_arm_only_fixed_hand">
	<link name="torso:11">
		<visual>
			<geometry>
				<mesh filename="meshes/torso_iam_fb80b350.STL" scale="0.001 0.001 0.001"/>
			</geometry>
			<origin rpy="0 0 0" xyz="-0.026368 -0.075212 0"/>
			<material name="torso:11_color">
				<color rgba="0.270588 0.270588 0.270588 1"/>
			</material>
		</visual>
		<collision>
			<geometry>
				<mesh filename="meshes/torso_iam_fb80b350.STL" scale="0.001 0.001 0.001"/>
			</geometry>
			<origin rpy="0 0 0" xyz="-0.026368 -0.075212 0"/>
		</collision>
		<inertial>
			<mass value="0.607828"/>
			<inertia ixx="0.006338" ixy="0.000004" ixz="0.000248" iyy="0.005208" iyz="0.000001" izz="0.002162"/>
			<origin rpy="0 0 0" xyz="0.01632 -0.000121 0.124348"/>
		</inertial>
	</link>
	<link name="right_shoulder:11">
		<visual>
			<geometry>
				<mesh filename="meshes/right_shoulder_up_iam_34db21c8.STL" scale="0.001 0.001 0.001"/>
			</geometry>
			<origin rpy="0 0 0" xyz="-0.062271 0.032843 -0.74045"/>
			<material name="right_shoulder:11_color">
				<color rgba="0.176471 0.176471 0.176471 1"/>
			</material>
		</visual>
		<collision>
			<geometry>
				<mesh filename="meshes/right_shoulder_up_iam_34db21c8.STL" scale="0.001 0.001 0.001"/>
			</geometry>
			<origin rpy="0 0 0" xyz="-0.062271 0.032843 -0.74045"/>
		</collision>
		<inertial>
			<mass value="0.084038"/>
			<inertia ixx="0.000026" ixy="-0.000001" ixz="-0.000002" iyy="0.000034" iyz="-0" izz="0.000033"/>
			<origin rpy="0 0 0" xyz="0.005637 0.000876 0.033153"/>
		</inertial>
	</link>
	<joint name="r_shoulder_z" type="revolute">
		<parent link="torso:11"/>
		<child link="right_shoulder:11"/>
		<origin rpy="0 0 -0.20444" xyz="0.026783 -0.049912 0.223501"/>
		<axis xyz="0 0 1"/>
		<limit effort="30" lower="-1.745" upper="2.182" velocity="1"/>
	</joint>
	<link name="right_collarbone:11">
		<visual>
			<geometry>
				<mesh filename="meshes/right_upper_arm_iam_e3e9c979.STL" scale="0.001 0.001 0.001"/>
			</geometry>
			<origin rpy="0 0 0" xyz="-0.0285 -0.054827 -0.000102"/>
			<material name="right_collarbone:11_color">
				<color rgba="0.176471 0.176471 0.176471 1"/>
			</material>
		</visual>
		<collision>
			<geometry>
				<mesh filename="meshes/right_upper_arm_iam_e3e9c979.STL" scale="0.001 0.001 0.001"/>
			</geometry>
			<origin rpy="0 0 0" xyz="-0.0285 -0.054827 -0.000102"/>
		</collision>
		<inertial>
			<mass value="0.024811"/>
			<inertia ixx="0.000014" ixy="-0" ixz="0" iyy="0.000011" iyz="-0.000001" izz="0.000019"/>
			<origin rpy="0 0 0" xyz="-0 -0.041345 -0.002364"/>
		</inertial>
	</link>
	<joint name="r_shoulder_y" type="revolute">
		<parent link="right_shoulder:11"/>
		<child link="right_collarbone:11"/>
		<origin rpy="0 0 0.20444" xyz="0.026211 -0.018056 0.037"/>
		<axis xyz="0 -1 0"/>
		<limit effort="30" lower="-3.142" upper="3.124" velocity="1"/>
	</joint>
	<link name="right_upper_arm:11">
		<visual>
			<geometry>
				<mesh filename="meshes/right_lower_arm1_iam_65a34910.STL" scale="0.001 0.001 0.001"/>
			</geometry>
			<origin rpy="0 0 0" xyz="-0.044001 -0.021 -0.139458"/>
			<material name="right_upper_arm:11_color">
				<color rgba="0.176471 0.176471 0.176471 1"/>
			</material>
		</visual>
		<collision>
			<geometry>
				<mesh filename="meshes/right_lower_arm1_iam_65a34910.STL" scale="0.001 0.001 0.001"/>
			</geometry>
			<origin rpy="0 0 0" xyz="-0.044001 -0.021 -0.139458"/>
		</collision>
		<inertial>
			<mass value="0.189729"/>
			<inertia ixx="0.000851" ixy="0" ixz="0" iyy="0.000851" iyz="-0.000005" izz="0.000048"/>
			<origin rpy="0 0 0" xyz="-0.02306 -0.000321 -0.0866"/>
		</inertial>
	</link>
	<joint name="r_arm_x" type="revolute">
		<parent link="right_collarbone:11"/>
		<child link="right_upper_arm:11"/>
		<origin rpy="0 0 0" xyz="0.0245 -0.073664 -0.022853"/>
		<axis xyz="1 0 0"/>
		<limit effort="30" lower="-3.002" upper="1.8675" velocity="1"/>
	</joint>
	<link name="right_lower_arm:11">
		<visual>
			<geometry>
				<mesh filename="meshes/right_wrist_iam_771ea33e.STL" scale="0.001 0.001 0.001"/>
			</geometry>
			<origin rpy="0 0 0" xyz="-0.0168 -0.0018 -0.123873"/>
			<material name="right_lower_arm:11_color">
				<color rgba="0.176471 0.176471 0.176471 1"/>
			</material>
		</visual>
		<collision>
			<geometry>
				<mesh filename="meshes/right_wrist_iam_771ea33e.STL" scale="0.001 0.001 0.001"/>
			</geometry>
			<origin rpy="0 0 0" xyz="-0.0168 -0.0018 -0.123873"/>
		</collision>
		<inertial>
			<mass value="0.076793"/>
			<inertia ixx="0.000104" ixy="-0" ixz="-0" iyy="0.000095" iyz="-0.000002" izz="0.000021"/>
			<origin rpy="0 0 0" xyz="0 0.022485 -0.081055"/>
		</inertial>
	</link>
	<joint name="r_elbow_y" type="revolute">
		<parent link="right_upper_arm:11"/>
		<child link="right_lower_arm:11"/>
		<origin rpy="0 -1.57 0" xyz="-0.023001 -0.024001 -0.1732"/> <!-- rpy="0 0 0" -->
		<axis xyz="0 1 0"/>
		<limit effort="30" lower="-0.175" upper="3.315" velocity="1"/> <!-- lower="-1.745" upper="1.745" -->
	</joint>
	<link name="right_wrist:11">
		<visual>
			<geometry>
				<mesh filename="meshes/right_wrist_iam_81504746.STL" scale="0.001 0.001 0.001"/>
			</geometry>
			<origin rpy="0 0 0" xyz="-0.000319 0.006617 -0.070181"/>
			<material name="right_wrist:11_color">
				<color rgba="0.74902 0.74902 0.74902 1"/>
			</material>
		</visual>
		<collision>
			<geometry>
				<mesh filename="meshes/right_wrist_iam_81504746.STL" scale="0.001 0.001 0.001"/>
			</geometry>
			<origin rpy="0 0 0" xyz="-0.000319 0.006617 -0.070181"/>
		</collision>
		<inertial>
			<mass value="0.028397"/>
			<inertia ixx="0.000043" ixy="-0" ixz="0.000004" iyy="0.000058" iyz="-0.000007" izz="0.000029"/>
			<origin rpy="0 0 0" xyz="0.000031 -0.011056 -0.0675"/>
		</inertial>
	</link>
	<joint name="r_wrist_z" type="revolute">
		<parent link="right_lower_arm:11"/>
		<child link="right_wrist:11"/>
		<origin rpy="0 0 0.028946" xyz="0 0.0102 -0.12605"/>
		<axis xyz="0 0 1"/>
		<limit effort="30" lower="-1.571" upper="1.571" velocity="1"/>
	</joint>
	<link name="right_palm:11">
		<visual>
			<geometry>
				<mesh filename="meshes/right_palm_iam_583b22df.STL" scale="0.001 0.001 0.001"/>
			</geometry>
			<origin rpy="0 0 0" xyz="-0.022933 0.001906 -0.017233"/>
			<material name="right_palm:11_color">
				<color rgba="0.74902 0.74902 0.74902 1"/>
			</material>
		</visual>
		<collision>
			<geometry>
				<mesh filename="meshes/right_palm_iam_583b22df.STL" scale="0.001 0.001 0.001"/>
			</geometry>
			<origin rpy="0 0 0" xyz="-0.022933 0.001906 -0.017233"/>
		</collision>
		<inertial>
			<mass value="0.005332"/>
			<inertia ixx="0.000015" ixy="0.000001" ixz="-0.000004" iyy="0.000017" iyz="0.000004" izz="0.000006"/>
			<origin rpy="0 0 0" xyz="-0.029511 0.002253 -0.023968"/>
		</inertial>
	</link>
	<joint name="r_wrist_x" type="revolute">
		<parent link="right_wrist:11"/>
		<child link="right_palm:11"/>
		<origin rpy="-0.433097 0 0" xyz="0.023416 0.006052 -0.070337"/>
		<axis xyz="1 0 0"/>
		<limit effort="30" lower="0" upper="0.872665" velocity="1"/>
	</joint>
	<link name="finger_segment:23">
		<visual>
			<geometry>
				<mesh filename="meshes/finger_segment_ipt_50d2a7f4.STL" scale="0.001 0.001 0.001"/>
			</geometry>
			<origin rpy="0 0 0" xyz="-0.006681 -0.015507 -0.007416"/>
			<material name="finger_segment:23_color">
				<color rgba="0.74902 0.74902 0.74902 1"/>
			</material>
		</visual>
		<collision>
			<geometry>
				<mesh filename="meshes/finger_segment_ipt_50d2a7f4.STL" scale="0.001 0.001 0.001"/>
			</geometry>
			<origin rpy="0 0 0" xyz="-0.006681 -0.015507 -0.007416"/>
		</collision>
		<inertial>
			<mass value="0.000009"/>
			<inertia ixx="0" ixy="0" ixz="-0" iyy="0" iyz="0" izz="0"/>
			<origin rpy="0 0 0" xyz="0.004909 0.000556 -0.005751"/>
		</inertial>
	</link>
	<joint name="r_indexfingers_x" type="fixed">
		<parent link="right_palm:11"/>
		<child link="finger_segment:23"/>
		<origin rpy="-0.578103 0.062904 -3.141593" xyz="-0.001139 0.006226 -0.040004"/>
		<axis xyz="0.998022 0.00962907 0.0621208"/>
		<limit effort="30" lower="-1.309" upper="0" velocity="1"/>
	</joint>
	<link name="finger_segment:13">
		<visual>
			<geometry>
				<mesh filename="meshes/finger_segment_ipt_50d2a7f4.STL" scale="0.001 0.001 0.001"/>
			</geometry>
			<origin rpy="0 0 0" xyz="-0.006181 -0.015507 -0.007417"/>
			<material name="finger_segment:13_color">
				<color rgba="0.74902 0.74902 0.74902 1"/>
			</material>
		</visual>
		<collision>
			<geometry>
				<mesh filename="meshes/finger_segment_ipt_50d2a7f4.STL" scale="0.001 0.001 0.001"/>
			</geometry>
			<origin rpy="0 0 0" xyz="-0.006181 -0.015507 -0.007417"/>
		</collision>
		<inertial>
			<mass value="0.000009"/>
			<inertia ixx="0" ixy="0" ixz="-0" iyy="0" iyz="0" izz="0"/>
			<origin rpy="0 0 0" xyz="0.005409 0.000556 -0.005751"/>
		</inertial>
	</link>
	<joint name="r_indexfinger_1st_x" type="fixed">
		<parent link="finger_segment:23"/>
		<child link="finger_segment:13"/>
		<origin rpy="-0.095246 0 0" xyz="-0.0005 0 -0.015999"/>
		<axis xyz="0.998022 0.00962907 0.0621208"/>
		<limit effort="30" lower="-1.309" upper="0" velocity="1"/>
	</joint>
	<link name="fingertip:13">
		<visual>
			<geometry>
				<mesh filename="meshes/fingertip_ipt_8417b8a9.STL" scale="0.001 0.001 0.001"/>
			</geometry>
			<origin rpy="0 0 0" xyz="0.005514 0.000374 -0.010171"/>
			<material name="fingertip:13_color">
				<color rgba="0.74902 0.74902 0.74902 1"/>
			</material>
		</visual>
		<collision>
			<geometry>
				<mesh filename="meshes/fingertip_ipt_8417b8a9.STL" scale="0.001 0.001 0.001"/>
			</geometry>
			<origin rpy="0 0 0" xyz="0.005514 0.000374 -0.010171"/>
		</collision>
		<inertial>
			<mass value="0.000008"/>
			<inertia ixx="0" ixy="-0" ixz="-0" iyy="0" iyz="-0" izz="0"/>
			<origin rpy="0 0 0" xyz="0.005013 0.000408 -0.010216"/>
		</inertial>
	</link>
	<joint name="r_indexfinger_2nd_x" type="fixed">
		<parent link="finger_segment:13"/>
		<child link="fingertip:13"/>
		<origin rpy="-0.109614 0 0" xyz="0 -0 -0.016"/>
		<axis xyz="0.998022 0.00962907 0.0621208"/>
		<limit effort="30" lower="-1.309" upper="0" velocity="1"/>
	</joint>
	<link name="finger_segment:22">
		<visual>
			<geometry>
				<mesh filename="meshes/finger_segment_ipt_50d2a7f4.STL" scale="0.001 0.001 0.001"/>
			</geometry>
			<origin rpy="0 0 0" xyz="-0.006681 -0.015507 -0.007416"/>
			<material name="finger_segment:22_color">
				<color rgba="0.74902 0.74902 0.74902 1"/>
			</material>
		</visual>
		<collision>
			<geometry>
				<mesh filename="meshes/finger_segment_ipt_50d2a7f4.STL" scale="0.001 0.001 0.001"/>
			</geometry>
			<origin rpy="0 0 0" xyz="-0.006681 -0.015507 -0.007416"/>
		</collision>
		<inertial>
			<mass value="0.000009"/>
			<inertia ixx="0" ixy="0" ixz="-0" iyy="0" iyz="0" izz="0"/>
			<origin rpy="0 0 0" xyz="0.004909 0.000556 -0.005751"/>
		</inertial>
	</link>
	<joint name="r_ringfingers_x" type="fixed">
		<parent link="right_palm:11"/>
		<child link="finger_segment:22"/>
		<origin rpy="-0.569851 -0.062904 -3.141593" xyz="-0.035879 0.006226 -0.040569"/>
		<axis xyz="0.998022 -0.00962907 -0.0621208"/>
		<limit effort="30" lower="-1.309" upper="0" velocity="1"/>
	</joint>
	<link name="finger_segment:12">
		<visual>
			<geometry>
				<mesh filename="meshes/finger_segment_ipt_50d2a7f4.STL" scale="0.001 0.001 0.001"/>
			</geometry>
			<origin rpy="0 0 0" xyz="-0.006181 -0.015507 -0.007417"/>
			<material name="finger_segment:12_color">
				<color rgba="0.74902 0.74902 0.74902 1"/>
			</material>
		</visual>
		<collision>
			<geometry>
				<mesh filename="meshes/finger_segment_ipt_50d2a7f4.STL" scale="0.001 0.001 0.001"/>
			</geometry>
			<origin rpy="0 0 0" xyz="-0.006181 -0.015507 -0.007417"/>
		</collision>
		<inertial>
			<mass value="0.000009"/>
			<inertia ixx="0" ixy="0" ixz="-0" iyy="0" iyz="0" izz="0"/>
			<origin rpy="0 0 0" xyz="0.005409 0.000556 -0.005752"/>
		</inertial>
	</link>
	<joint name="r_ringfinger_1st_x" type="fixed">
		<parent link="finger_segment:22"/>
		<child link="finger_segment:12"/>
		<origin rpy="-0.095245 0 0" xyz="-0.0005 0 -0.016"/>
		<axis xyz="0.998022 -0.00962907 -0.0621208"/>
		<limit effort="30" lower="-1.309" upper="0" velocity="1"/>
	</joint>
	<link name="fingertip:12">
		<visual>
			<geometry>
				<mesh filename="meshes/fingertip_ipt_8417b8a9.STL" scale="0.001 0.001 0.001"/>
			</geometry>
			<origin rpy="0 0 0" xyz="0.005514 0.000373 -0.010171"/>
			<material name="fingertip:12_color">
				<color rgba="0.74902 0.74902 0.74902 1"/>
			</material>
		</visual>
		<collision>
			<geometry>
				<mesh filename="meshes/fingertip_ipt_8417b8a9.STL" scale="0.001 0.001 0.001"/>
			</geometry>
			<origin rpy="0 0 0" xyz="0.005514 0.000373 -0.010171"/>
		</collision>
		<inertial>
			<mass value="0.000008"/>
			<inertia ixx="0" ixy="-0" ixz="-0" iyy="0" iyz="-0" izz="0"/>
			<origin rpy="0 0 0" xyz="0.005013 0.000407 -0.010215"/>
		</inertial>
	</link>
	<joint name="r_ringfinger_2nd_x" type="fixed">
		<parent link="finger_segment:12"/>
		<child link="fingertip:12"/>
		<origin rpy="-0.109614 0 0" xyz="0 -0 -0.016"/>
		<axis xyz="0.998022 -0.00962907 -0.0621208"/>
		<limit effort="30" lower="-1.309" upper="0" velocity="1"/>
	</joint>
	<link name="finger_segment:21">
		<visual>
			<geometry>
				<mesh filename="meshes/finger_segment_ipt_50d2a7f4.STL" scale="0.001 0.001 0.001"/>
			</geometry>
			<origin rpy="0 0 0" xyz="-0.006681 -0.015507 -0.007417"/>
			<material name="finger_segment:21_color">
				<color rgba="0.74902 0.74902 0.74902 1"/>
			</material>
		</visual>
		<collision>
			<geometry>
				<mesh filename="meshes/finger_segment_ipt_50d2a7f4.STL" scale="0.001 0.001 0.001"/>
			</geometry>
			<origin rpy="0 0 0" xyz="-0.006681 -0.015507 -0.007417"/>
		</collision>
		<inertial>
			<mass value="0.000009"/>
			<inertia ixx="0" ixy="0" ixz="-0" iyy="0" iyz="0" izz="0"/>
			<origin rpy="0 0 0" xyz="0.004909 0.000556 -0.005752"/>
		</inertial>
	</link>
	<joint name="r_thumb_x" type="fixed">
		<parent link="right_palm:11"/>
		<child link="finger_segment:21"/>
		<origin rpy="1.915504 0 0" xyz="-0.0275 0.0199 -0.00842"/>
		<axis xyz="1 0 0"/>
		<limit effort="30" lower="-1.309" upper="0" velocity="1"/>
	</joint>
	<link name="finger_segment:11">
		<visual>
			<geometry>
				<mesh filename="meshes/finger_segment_ipt_50d2a7f4.STL" scale="0.001 0.001 0.001"/>
			</geometry>
			<origin rpy="0 0 0" xyz="-0.006181 -0.015507 -0.007416"/>
			<material name="finger_segment:11_color">
				<color rgba="0.74902 0.74902 0.74902 1"/>
			</material>
		</visual>
		<collision>
			<geometry>
				<mesh filename="meshes/finger_segment_ipt_50d2a7f4.STL" scale="0.001 0.001 0.001"/>
			</geometry>
			<origin rpy="0 0 0" xyz="-0.006181 -0.015507 -0.007416"/>
		</collision>
		<inertial>
			<mass value="0.000009"/>
			<inertia ixx="0" ixy="0" ixz="-0" iyy="0" iyz="0" izz="0"/>
			<origin rpy="0 0 0" xyz="0.005409 0.000557 -0.005751"/>
		</inertial>
	</link>
	<joint name="r_thumb_1st_x" type="fixed">
		<parent link="finger_segment:21"/>
		<child link="finger_segment:11"/>
		<origin rpy="-0.095246 0 0" xyz="-0.0005 -0.000001 -0.016001"/>
		<axis xyz="1 0 0"/>
		<limit effort="30" lower="-1.309" upper="0" velocity="1"/>
	</joint>
	<link name="fingertip:11">
		<visual>
			<geometry>
				<mesh filename="meshes/fingertip_ipt_8417b8a9.STL" scale="0.001 0.001 0.001"/>
			</geometry>
			<origin rpy="0 0 0" xyz="0.005514 0.000374 -0.010171"/>
			<material name="fingertip:11_color">
				<color rgba="0.74902 0.74902 0.74902 1"/>
			</material>
		</visual>
		<collision>
			<geometry>
				<mesh filename="meshes/fingertip_ipt_8417b8a9.STL" scale="0.001 0.001 0.001"/>
			</geometry>
			<origin rpy="0 0 0" xyz="0.005514 0.000374 -0.010171"/>
		</collision>
		<inertial>
			<mass value="0.000008"/>
			<inertia ixx="0" ixy="-0" ixz="-0" iyy="0" iyz="-0" izz="0"/>
			<origin rpy="0 0 0" xyz="0.005013 0.000408 -0.010216"/>
		</inertial>
	</link>
	<joint name="r_thumb_2nd_x" type="fixed">
		<parent link="finger_segment:11"/>
		<child link="fingertip:11"/>
		<origin rpy="-0.109614 0 0" xyz="0 0.000001 -0.015999"/>
		<axis xyz="1 0 0"/>
		<limit effort="30" lower="-1.309" upper="0" velocity="1"/>
	</joint>
	<link name="neck:11">
		<visual>
			<geometry>
				<mesh filename="meshes/neck_iam_61141f4f.STL" scale="0.001 0.001 0.001"/>
			</geometry>
			<origin rpy="0 0 0" xyz="-0.015583 -0.0205 0"/>
			<material name="neck:11_color">
				<color rgba="0.74902 0.74902 0.74902 1"/>
			</material>
		</visual>
		<collision>
			<geometry>
				<mesh filename="meshes/neck_iam_61141f4f.STL" scale="0.001 0.001 0.001"/>
			</geometry>
			<origin rpy="0 0 0" xyz="-0.015583 -0.0205 0"/>
		</collision>
		<inertial>
			<mass value="0.090439"/>
			<inertia ixx="0.00006" ixy="-0" ixz="-0" iyy="0.000056" iyz="-0.000001" izz="0.000019"/>
			<origin rpy="0 0 0" xyz="0 0.000266 0.050352"/>
		</inertial>
	</link>
	<joint name="head_z" type="fixed">
		<parent link="torso:11"/>
		<child link="neck:11"/>
		<origin rpy="0 0 0" xyz="0.001283 -0.000212 0.231001"/>
		<axis xyz="0 0 1"/>
		<limit effort="30" lower="-3.124" upper="3.142" velocity="1"/>
	</joint>
	<link name="head:21">
		<visual>
			<geometry>
				<mesh filename="meshes/head_iam_b9cf2ea.STL" scale="0.001 0.001 0.001"/>
			</geometry>
			<origin rpy="0 0 0" xyz="-0.003998 -0.016462 0.04478"/>
			<material name="head:21_color">
				<color rgba="0.74902 0.74902 0.74902 1"/>
			</material>
		</visual>
		<collision>
			<geometry>
				<mesh filename="meshes/head_iam_b9cf2ea.STL" scale="0.001 0.001 0.001"/>
			</geometry>
			<origin rpy="0 0 0" xyz="-0.003998 -0.016462 0.04478"/>
		</collision>
		<inertial>
			<mass value="0.294137"/>
			<inertia ixx="0.001424" ixy="-0" ixz="0.000083" iyy="0.00159" iyz="-0.000002" izz="0.001485"/>
			<origin rpy="0 0 0" xyz="0.01525 -0.023771 0.09423"/>
		</inertial>
	</link>
	<joint name="head_y" type="fixed">
		<parent link="neck:11"/>
		<child link="head:21"/>
		<origin rpy="0 0.6 0" xyz="0 0.023001 0.0745"/>
		<axis xyz="0 1 0"/>
		<limit effort="30" lower="-1.553" upper="1.379" velocity="1"/>
	</joint>
</robot>
