<?xml version="1.0" ?>
<robot name="niryo_ned">
  <link name="world"/>
  <joint name="joint_world" type="fixed">
    <parent link="world"/>
    <child link="base_link"/>
    <origin xyz="0 0 0" rpy="0 0 0"/>
  </joint>
  <link name="base_link">
    <inertial>
      <origin xyz="-0.00240796011216664 -0.00591764669105095 0.0515774030380053" rpy="0 0 0"/>
      <mass value="0.999243361008122"/>
      <inertia ixx="0.002" ixy="0.0" ixz="0.0" iyy="0.002" iyz="0.0" izz="0.004"/>
    </inertial>
    <visual>
      <origin xyz="0 0 0" rpy="0 0 0"/>
      <geometry>
        <mesh filename="meshes/ned/collada/base_link.dae"/>
      </geometry>
    </visual>
    <collision>
      <origin xyz="0 0 0" rpy="0 0 0"/>
      <geometry>
        <mesh filename="meshes/ned/stl/base_link.stl"/>
      </geometry>
    </collision>
  </link>
  <joint name="joint_1" type="revolute">
    <origin xyz="0 0 0.1065" rpy="0 0 0"/>
    <parent link="base_link"/>
    <child link="shoulder_link"/>
    <axis xyz="0 0 1"/>
    <limit effort="10.0" velocity="2.2" lower="-2.9670597283905553" upper="2.9670597283905553"/>
  </joint>
  <link name="shoulder_link">
    <inertial>
      <origin xyz="-0.0307310771918448 0.00581074732334248 0.0302277607274943" rpy="0 0 0"/>
      <mass value="0.474558968160783"/>
      <inertia ixx="0.0015" ixy="0.0" ixz="0.0" iyy="0.0015" iyz="0.0" izz="0.0015"/>
    </inertial>
    <visual>
      <origin xyz="0 0 0" rpy="0 0 0"/>
      <geometry>
        <mesh filename="meshes/ned/collada/shoulder_link.dae"/>
      </geometry>
    </visual>
    <collision>
      <origin xyz="0 0 0" rpy="0 0 0"/>
      <geometry>
        <mesh filename="meshes/ned/stl/shoulder_link.stl"/>
      </geometry>
    </collision>
  </link>
  <joint name="joint_2" type="revolute">
    <origin xyz="0 0 0.065" rpy="1.570796326795 -1.570796326795 0"/>
    <parent link="shoulder_link"/>
    <child link="arm_link"/>
    <axis xyz="0 0 1"/>
    <limit effort="10.0" velocity="2.2" lower="-1.9100883333827199" upper="0.6101671064972578"/>
  </joint>
  <link name="arm_link">
    <inertial>
      <origin xyz="0.116485160625991 -0.00141190194997476 -0.00338105503061108" rpy="0 0 0"/>
      <mass value="0.513332159226246"/>
      <inertia ixx="0.0015" ixy="0.0" ixz="0.0" iyy="0.0015" iyz="0.0" izz="0.0015"/>
    </inertial>
    <visual>
      <origin xyz="0 0 0" rpy="0 0 0"/>
      <geometry>
        <mesh filename="meshes/ned/collada/arm_link.dae"/>
      </geometry>
    </visual>
    <collision>
      <origin xyz="0 0 0" rpy="0 0 0"/>
      <geometry>
        <mesh filename="meshes/ned/stl/arm_link.stl"/>
      </geometry>
    </collision>
  </link>
  <joint name="joint_3" type="revolute">
    <origin xyz="0.221 -0.012 0" rpy="0 0 -1.570796326795"/>
    <parent link="arm_link"/>
    <child link="elbow_link"/>
    <axis xyz="0 0 1"/>
    <limit effort="7.0" velocity="2.0" lower="-1.3400637996813345" upper="1.5700981950942021"/>
  </joint>
  <link name="elbow_link">
    <inertial>
      <origin xyz="0.00840548736069937 0.0235132719991579 0.00139784606943909" rpy="0 0 0"/>
      <mass value="0.201038841892435"/>
      <inertia ixx="0.0015" ixy="0.0" ixz="0.0" iyy="0.0015" iyz="0.0" izz="0.0015"/>
    </inertial>
    <visual>
      <origin xyz="0 0 0" rpy="0 0 0"/>
      <geometry>
        <mesh filename="meshes/ned/collada/elbow_link.dae"/>
      </geometry>
    </visual>
    <collision>
      <origin xyz="0 0 0" rpy="0 0 0"/>
      <geometry>
        <mesh filename="meshes/ned/stl/elbow_link.stl"/>
      </geometry>
    </collision>
  </link>
  <joint name="joint_4" type="revolute">
    <origin xyz="0.047 0.0325 0" rpy="0 1.570796326795 0"/>
    <parent link="elbow_link"/>
    <child link="forearm_link"/>
    <axis xyz="0 0 1"/>
    <limit effort="7.0" velocity="2.0" lower="-2.090031779263347" upper="2.090031779263347"/>
  </joint>
  <link name="forearm_link">
    <inertial>
      <origin xyz="-0.00811345462189901 -0.000135618649565461 0.107402242790047" rpy="0 0 0"/>
      <mass value="0.203543862275952"/>
      <inertia ixx="0.0015" ixy="0.0" ixz="0.0" iyy="0.0015" iyz="0.0" izz="0.0015"/>
    </inertial>
    <visual>
      <origin xyz="0 0 0" rpy="0 0 0"/>
      <geometry>
        <mesh filename="meshes/ned/collada/forearm_link.dae"/>
      </geometry>
    </visual>
    <collision>
      <origin xyz="0 0 0" rpy="0 0 0"/>
      <geometry>
        <mesh filename="meshes/ned/stl/forearm_link.stl"/>
      </geometry>
    </collision>
  </link>
  <joint name="joint_5" type="revolute">
    <origin xyz="0 0 0.188" rpy="3.14159265359 -1.570796326795 3.14159265359"/>
    <parent link="forearm_link"/>
    <child link="wrist_link"/>
    <axis xyz="0 0 1"/>
    <limit effort="6.0" velocity="2.0" lower="-1.9200367101190883" upper="1.0501646109250573"/>
  </joint>
  <link name="wrist_link">
    <inertial>
      <origin xyz="-0.0193227036920796 -0.00157014407079775 0.000275751023741896" rpy="0 0 0"/>
      <mass value="0.0403595377880338"/>
      <inertia ixx="0.0015" ixy="0.0" ixz="0.0" iyy="0.0015" iyz="0.0" izz="0.0015"/>
    </inertial>
    <visual>
      <origin xyz="0 0 0" rpy="0 0 0"/>
      <geometry>
        <mesh filename="meshes/ned/collada/wrist_link.dae"/>
      </geometry>
    </visual>
    <collision>
      <origin xyz="0 0 0" rpy="0 0 0"/>
      <geometry>
        <mesh filename="meshes/ned/stl/wrist_link.stl"/>
      </geometry>
    </collision>
  </link>
  <joint name="joint_6" type="revolute">
    <origin xyz="0.0197 0.00925 0" rpy="0 1.570796326795 0"/>
    <parent link="wrist_link"/>
    <child link="hand_link"/>
    <axis xyz="0 0 1"/>
    <limit effort="5.0" velocity="2.0" lower="-2.530029283691147" upper="2.530029283691147"/>
  </joint>
  <link name="hand_link">
    <inertial>
      <origin xyz="-5.84141230982198E-10 -1.35851692194544E-05 0.00881600136229516" rpy="0 0 0"/>
      <mass value="0.0148769800713074"/>
      <inertia ixx="0.0015" ixy="0.0" ixz="0.0" iyy="0.0015" iyz="0.0" izz="0.0015"/>
    </inertial>
    <visual>
      <origin xyz="0 0 0" rpy="0 0 0"/>
      <geometry>
        <mesh filename="meshes/ned/collada/hand_link.dae"/>
      </geometry>
    </visual>
    <collision>
      <origin xyz="0 0 0" rpy="0 0 0"/>
      <geometry>
        <mesh filename="meshes/ned/stl/hand_link.stl"/>
      </geometry>
    </collision>
  </link>
  <joint name="hand_tool_joint" type="fixed">
    <parent link="hand_link"/>
    <child link="tool_link"/>
    <origin xyz="0 0 0.0215" rpy="-1.570796326795 -1.570796326795 0"/>
  </joint>
  <link name="tool_link">
    <inertial>
      <origin xyz="0 0 0" rpy="0 0 0"/>
      <mass value="0"/>
      <inertia ixx="0" ixy="0" ixz="0" iyy="0" iyz="0" izz="0"/>
    </inertial>
  </link>
  <joint name="joint_to_gripper" type="fixed">
    <parent link="tool_link"/>
    <child link="base_gripper_1"/>
    <origin xyz="0 0 0.005" rpy="0 1.570796326795 1.570796326795"/>
  </joint>
  <link name="base_gripper_1">
    <inertial>
      <origin xyz="0.0028582 0.0022204 0.023772" rpy="0 0 0"/>
      <mass value="0.001"/>
      <inertia ixx="1E-06" ixy="0.0" ixz="0.0" iyy="1E-06" iyz="0.0" izz="1E-06"/>
    </inertial>
    <visual>
      <origin xyz="0 0 0" rpy="0 0 0"/>
      <geometry>
        <mesh filename="meshes/gripper_1/base_gripper_1.STL"/>
      </geometry>
    </visual>
    <collision>
      <origin xyz="0 0 0" rpy="0 0 0"/>
      <geometry>
        <mesh filename="meshes/gripper_1/base_gripper_1.STL"/>
      </geometry>
    </collision>
  </link>
  <link name="mors_1">
    <inertial>
      <origin xyz="-0.0049739 0.0067393 -0.023929" rpy="0 0 0"/>
      <mass value="0.0067248"/>
      <inertia ixx="1.1778E-06" ixy="-2.1129E-08" ixz="1.0185E-07" iyy="1.3054E-06" iyz="1.7669E-07" izz="4.3534E-07"/>
    </inertial>
    <visual>
      <origin xyz="0 0 0" rpy="0 0 0"/>
      <geometry>
        <mesh filename="meshes//gripper_1/mors_1.STL"/>
      </geometry>
      <material name="">
        <color rgba="0.49804 0.49804 0.49804 1"/>
      </material>
    </visual>
    <collision>
      <origin xyz="0 0 0" rpy="0 0 0"/>
      <geometry>
        <mesh filename="meshes//gripper_1/mors_1.STL"/>
      </geometry>
    </collision>
  </link>
  <joint name="joint_base_to_mors_1" type="fixed"> <!-- <joint name="joint_base_to_mors_1" type="prismatic"> -->
    <origin xyz="0.01455 -0.0796 0.0196137" rpy="1.5708 0 0"/> <!-- <origin xyz="0.01455 -0.0796 0.0096137" rpy="1.5708 0 0"/> -->
    <parent link="base_gripper_1"/>
    <child link="mors_1"/>
    <axis xyz="0 1 0"/>
    <limit lower="-0.02" upper="0" effort="1" velocity="5"/> <!-- <limit lower="-0.01" upper="0.01" effort="1" velocity="5"/> -->
  </joint>
  <link name="mors_2">
    <inertial>
      <origin xyz="-0.0049739 -0.0067393 -0.023929" rpy="0 0 0"/>
      <mass value="0.0067248"/>
      <inertia ixx="1.1778E-06" ixy="2.1129E-08" ixz="1.0185E-07" iyy="1.3054E-06" iyz="-1.7669E-07" izz="4.3534E-07"/>
    </inertial>
    <visual>
      <origin xyz="0 0 0" rpy="0 0 0"/>
      <geometry>
        <mesh filename="meshes/gripper_1/mors_2.STL"/>
      </geometry>
    </visual>
    <collision>
      <origin xyz="0 0 0" rpy="0 0 0"/>
      <geometry>
        <mesh filename="meshes/gripper_1/mors_2.STL"/>
      </geometry>
    </collision>
  </link>
  <joint name="joint_base_to_mors_2" type="fixed"> <!-- <joint name="joint_base_to_mors_2" type="prismatic"> -->
    <origin xyz="0.01455 -0.0796 -0.021066" rpy="1.5708 0 0"/> <!-- <origin xyz="0.01455 -0.0796 -0.011066" rpy="1.5708 0 0"/> -->
    <parent link="base_gripper_1"/>
    <child link="mors_2"/>
    <axis xyz="0 -1 0"/>
    <limit lower="-0.02" upper="0" effort="1" velocity="5"/> <!-- <limit lower="-0.01" upper="0.01" effort="1" velocity="5"/> -->
  </joint>
  <link name="endeffector">
    <visual>
      <origin rpy="0 0 0" xyz="0 0.0 0.0"/>
      <geometry>
        <sphere radius="0.01"/>
      </geometry>
      <material name="endeffector_color">
        <color rgba="1 0 0 0.25"/>
      </material>
    </visual>
    <inertial>
      <mass value="0"/>
      <inertia ixx="0" ixy="0" ixz="-0" iyy="0" iyz="0" izz="0"/>
      <origin rpy="0 0 0" xyz="0 0 0"/>
    </inertial>
  </link>
  <joint name="endeffector_joint" type="fixed">
    <parent link="base_gripper_1"/>
    <child link="endeffector"/>
    <origin rpy="0 0 0" xyz="0.007 -0.065 0"/>
  </joint>
</robot>

<!-- <link name="joint5_motor">
    <inertial>
      <origin xyz="-0.00811345462189901 -0.000135618649565461 0.107402242790047" rpy="0 0 0"/>
      <mass value="0.203543862275952"/>
      <inertia ixx="0.0015" ixy="0.0" ixz="0.0" iyy="0.0015" iyz="0.0" izz="0.0015"/>
    </inertial>
    <visual>
      <origin xyz="-0.045 0.0 0.1765" rpy="0 0 0"/>
      <geometry>
        <box size="0.03 0.03 0.046"/> 
        <!-- <box size="0.0435 0.0285 0.0465"/> -->
      </geometry>
      <material name="motor_color">
        <color rgba="1 1 1 0"/>
      </material>
    </visual>
    <collision>
      <origin xyz="-0.045 0.0 0.1765" rpy="0 0 0"/>
      <geometry>
        <box size="0.03 0.03 0.046"/> 
        <!-- <box size="0.0435 0.0285 0.0465"/> -->
      </geometry>
    </collision>
  </link>
  <joint name="joint_test" type="fixed">
    <origin xyz="0 0 0" rpy="0 0 0"/>
    <parent link="forearm_link"/>
    <child link="joint5_motor"/>
  </joint> -->
